[1m[31mERROR   [0m test_successful_login:custom_logger.py:42 Test test_successful_login FAILED
[1m[31mERROR   [0m test_successful_login:custom_logger.py:43 Expecting value: line 1 column 1 (char 0)
Traceback (most recent call last):
  File "E:\PythonFramework\PythonPyTestFrameWorkAPI\venv\lib\site-packages\requests\models.py", line 960, in json
    return complexjson.loads(self.content.decode(encoding), **kwargs)
  File "C:\python\lib\json\__init__.py", line 346, in loads
    return _default_decoder.decode(s)
  File "C:\python\lib\json\decoder.py", line 337, in decode
    obj, end = self.raw_decode(s, idx=_w(s, 0).end())
  File "C:\python\lib\json\decoder.py", line 355, in raw_decode
    raise JSONDecodeError("Expecting value", s, err.value) from None
json.decoder.JSONDecodeError: Expecting value: line 1 column 1 (char 0)

During handling of the above exception, another exception occurred:

Traceback (most recent call last):
  File "E:\PythonFramework\PythonPyTestFrameWorkAPI\utils\custom_logger.py", line 38, in wrapper
    result = func(*args, **kwargs)
  File "E:\PythonFramework\PythonPyTestFrameWorkAPI\tests\test_api.py", line 35, in test_successful_login
    print(resp.json())
  File "E:\PythonFramework\PythonPyTestFrameWorkAPI\venv\lib\site-packages\requests\models.py", line 968, in json
    raise RequestsJSONDecodeError(e.msg, e.doc, e.pos)
requests.exceptions.JSONDecodeError: Expecting value: line 1 column 1 (char 0)
[32mINFO    [0m test_successful_login:custom_logger.py:46 Finished test: test_successful_login