[31m[1mERROR   [0m test_successful_login:custom_logger.py:42 Test test_successful_login FAILED
[31m[1mERROR   [0m test_successful_login:custom_logger.py:43 
Traceback (most recent call last):
  File "E:\PythonFramework\PythonPyTestFrameWorkAPI\utils\custom_logger.py", line 38, in wrapper
    result = func(*args, **kwargs)
  File "E:\PythonFramework\PythonPyTestFrameWorkAPI\tests\test_api.py", line 38, in test_successful_login
    assert_status_code(resp, 200)
  File "E:\PythonFramework\PythonPyTestFrameWorkAPI\utils\common.py", line 55, in assert_status_code
    assert response.status_code == expected_code
AssertionError
[32mINFO    [0m test_successful_login:custom_logger.py:46 Finished test: test_successful_login